<mujoco model="mobi_dex">
  <compiler angle="radian" meshdir="assets/"/>
  <option integrator="implicitfast"/>
  <asset>
    <mesh name="base_link" file="kinova_gen3/base_link.STL"/>
    <mesh name="shoulder_link" file="kinova_gen3/shoulder_link.STL"/>
    <mesh name="half_arm_1_link" file="kinova_gen3/half_arm_1_link.STL"/>
    <mesh name="half_arm_2_link" file="kinova_gen3/half_arm_2_link.STL"/>
    <mesh name="forearm_link" file="kinova_gen3/forearm_link.STL"/>
    <mesh name="spherical_wrist_1_link" file="kinova_gen3/spherical_wrist_1_link.STL"/>
    <mesh name="spherical_wrist_2_link" file="kinova_gen3/spherical_wrist_2_link.STL"/>
    <mesh name="bracelet_with_vision_link" file="kinova_gen3/bracelet_with_vision_link.STL"/>


    <mesh name="palm_lower" file="leap_hand/palm_lower.stl"/>
    <mesh name="mcp_joint" file="leap_hand/mcp_joint.stl"/>
    <mesh name="pip" file="leap_hand/pip.stl"/>
    <mesh name="dip" file="leap_hand/dip.stl"/>
    <mesh name="fingertip" file="leap_hand/fingertip.stl"/>
    <mesh name="thumb_pip" file="leap_hand/thumb_pip.stl"/>
    <mesh name="thumb_dip" file="leap_hand/thumb_dip.stl"/>
    <mesh name="thumb_fingertip" file="leap_hand/thumb_fingertip.stl"/>

  </asset>
  <worldbody>
    <!-- Mobile Base -->
    <body name="mobile_base" pos="0 0 0.1675"> <!-- Positioning the base off the ground -->
      <geom type="box" size=".2325 .2325 0.1675" contype="0" conaffinity="0" rgba=".75 .75 .75 1.0"/>
      <!-- Kinova Arm -->
      <body name="base_link" pos="0 0 0.1675">  <!-- Correctly offsetting the base_link -->
        <!-- <joint name="joint_mobile_base_and_kinova_base" pos="0 0 0" axis="0 0 1"/> -->
        <inertial pos="-0.000648 -0.000166 0.084487" quat="0.999294 0.00139618 -0.0118387 0.035636" mass="1.697" diaginertia="0.00462407 0.00449437 0.00207755"/>
        <geom type="mesh" contype="0" conaffinity="0" group="1" density="0" rgba="0.75294 0.75294 0.75294 1" mesh="base_link"/>
        <geom type="mesh" rgba="0.75294 0.75294 0.75294 1" mesh="base_link"/>
        <body name="shoulder_link" pos="0 0 0.15643" quat="-3.67321e-06 1 0 0">
          <inertial pos="-2.3e-05 -0.010364 -0.07336" quat="0.707051 0.0451246 -0.0453544 0.704263" mass="1.3773" diaginertia="0.00488868 0.00457 0.00135132"/>
          <joint name="joint_1" pos="0 0 0" axis="0 0 1" range="-3.0615 3.0615"/>
          <geom type="mesh" contype="0" conaffinity="0" group="1" density="0" rgba="0.75294 0.75294 0.75294 1" mesh="shoulder_link"/>
          <geom type="mesh" rgba="0.75294 0.75294 0.75294 1" mesh="shoulder_link"/>
          <body name="half_arm_1_link" pos="0 0.005375 -0.12838" quat="0.707105 0.707108 0 0">
            <inertial pos="-4.4e-05 -0.09958 -0.013278" quat="0.482348 0.516286 -0.516862 0.483366" mass="1.1636" diaginertia="0.0113017 0.011088 0.00102532"/>
            <joint name="joint_2" pos="0 0 0" axis="0 0 1" range="-2.24 2.24"/>
            <geom type="mesh" contype="0" conaffinity="0" group="1" density="0" rgba="0.75294 0.75294 0.75294 1" mesh="half_arm_1_link"/>
            <geom type="mesh" rgba="0.75294 0.75294 0.75294 1" mesh="half_arm_1_link"/>
            <body name="half_arm_2_link" pos="0 -0.21038 -0.006375" quat="0.707105 -0.707108 0 0">
              <inertial pos="-4.4e-05 -0.006641 -0.117892" quat="0.706144 0.0213722 -0.0209128 0.707437" mass="1.1636" diaginertia="0.0111633 0.010932 0.00100671"/>
              <joint name="joint_3" pos="0 0 0" axis="0 0 1" range="0.0801 6.2031"/>
              <geom type="mesh" contype="0" conaffinity="0" group="1" density="0" rgba="0.75294 0.75294 0.75294 1" mesh="half_arm_2_link"/>
              <geom type="mesh" rgba="0.75294 0.75294 0.75294 1" mesh="half_arm_2_link"/>
              <body name="forearm_link" pos="0 0.006375 -0.21038" quat="0.707105 0.707108 0 0">
                <inertial pos="-1.8e-05 -0.075478 -0.015006" quat="0.483678 0.515961 -0.515859 0.483455" mass="0.9302" diaginertia="0.00834839 0.008147 0.000598606"/>
                <joint name="joint_4" pos="0 0 0" axis="0 0 1" range="-2.57 2.57"/>
                <geom type="mesh" contype="0" conaffinity="0" group="1" density="0" rgba="0.75294 0.75294 0.75294 1" mesh="forearm_link"/>
                <geom type="mesh" rgba="0.75294 0.75294 0.75294 1" mesh="forearm_link"/>
                <body name="spherical_wrist_1_link" pos="0 -0.20843 -0.006375" quat="0.707105 -0.707108 0 0">
                  <inertial pos="1e-06 -0.009432 -0.063883" quat="0.703558 0.0707492 -0.0707492 0.703558" mass="0.6781" diaginertia="0.00165901 0.001596 0.000346988"/>
                  <joint name="joint_5" pos="0 0 0" axis="0 0 1" range="-3.0615 3.0615"/>
                  <geom type="mesh" contype="0" conaffinity="0" group="1" density="0" rgba="0.75294 0.75294 0.75294 1" mesh="spherical_wrist_1_link"/>
                  <geom type="mesh" rgba="0.75294 0.75294 0.75294 1" mesh="spherical_wrist_1_link"/>
                  <body name="spherical_wrist_2_link" pos="0 0.00017505 -0.10593" quat="0.707105 0.707108 0 0">
                    <inertial pos="1e-06 -0.045483 -0.00965" quat="0.44426 0.550121 -0.550121 0.44426" mass="0.6781" diaginertia="0.00170087 0.001641 0.00035013"/>
                    <joint name="joint_6" pos="0 0 0" axis="0 0 1" range="-2.09 2.09"/>
                    <geom type="mesh" contype="0" conaffinity="0" group="1" density="0" rgba="0.75294 0.75294 0.75294 1" mesh="spherical_wrist_2_link"/>
                    <geom type="mesh" rgba="0.75294 0.75294 0.75294 1" mesh="spherical_wrist_2_link"/>
                    <body name="bracelet_link" pos="0 -0.10593 -0.00017505" quat="0.707105 -0.707108 0 0">
                      <inertial pos="0.000281 0.011402 -0.029798" quat="0.394358 0.596779 -0.577293 0.393789" mass="0.5" diaginertia="0.000657336 0.000587019 0.000320645"/>
                      <joint name="joint_7" pos="0 0 0" axis="0 0 1" range="-1.4915 4.6315"/>
                      <geom type="mesh" contype="0" conaffinity="0" group="1" density="0" rgba="0.75294 0.75294 0.75294 1" mesh="bracelet_with_vision_link"/>
                      <geom type="mesh" rgba="0.75294 0.75294 0.75294 1" mesh="bracelet_with_vision_link"/>
                      <!-- <site name="attachment_site" rgba="1 0 0 1" size="0.01" pos="0 0 -0.061525" quat="0 1 0 0"/> -->
                      <site name="attachment_site" rgba="1 0 0 1" size="0.01" pos="0 0 -0.121525" quat="0 1 0 0"/>


                      <!-- LEAP HAND START -->
                      <body name="palm_lower" pos="0.03 -0.06 -0.07525" quat="0.707106781 0 0 -0.707106781">
                        <geom pos="-0.0200952 0.0257578 -0.0347224" quat="1 0 0 0" type="mesh" rgba="0.603922 0.14902 0.14902 1" mesh="palm_lower"/>
                        <body name="mcp_joint" pos="-0.00709525 0.0230578 -0.0187224" quat="0.5 0.5 0.5 -0.5">
                          <inertial pos="0 0 0" quat="0.388585 0.626468 -0.324549 0.592628" mass="0.044" diaginertia="1.47756e-05 1.31982e-05 6.0802e-06"/>
                          <joint name="leap_hand_1" pos="0 0 0" axis="0 0 -1" range="-0.314 2.23" actuatorfrcrange="-0.95 0.95"/>
                          <geom pos="0.0084069 0.00776624 0.0146574" quat="1 0 0 0" type="mesh" rgba="0.866667 0.866667 0.0509804 1" mesh="mcp_joint"/>
                          <body name="pip" pos="-0.0122 0.0381 0.0145" quat="0.5 -0.5 -0.5 0.5">
                            <inertial pos="0 0 0" quat="0.709913 0.704273 -0.000363156 0.00475427" mass="0.032" diaginertia="4.7981e-06 4.23406e-06 2.86184e-06"/>
                            <joint name="leap_hand_0" pos="0 0 0" axis="0 0 -1" range="-1.047 1.047" actuatorfrcrange="-0.95 0.95"/>
                            <geom pos="0.00964336 0.0003 0.000784034" quat="0.5 -0.5 -0.5 -0.5" type="mesh" rgba="0.74902 0.74902 0.74902 1" mesh="pip"/>
                            <body name="dip" pos="0.015 0.0143 -0.013" quat="0.5 0.5 -0.5 0.5">
                              <inertial pos="0 0 0" quat="-0.252689 0.659216 0.238844 0.666735" mass="0.037" diaginertia="6.68256e-06 6.24841e-06 5.02002e-06"/>
                              <joint name="leap_hand_2" pos="0 0 0" axis="0 0 -1" range="-0.506 1.885" actuatorfrcrange="-0.95 0.95"/>
                              <geom pos="0.0211334 -0.00843212 0.00978509" quat="0 -1 0 0" type="mesh" rgba="0.866667 0.866667 0.0509804 1" mesh="dip"/>
                              <body name="fingertip" pos="-4.08806e-09 -0.0361 0.0002">
                                <inertial pos="0 0 0" quat="0.706755 0.706755 0.0223155 0.0223155" mass="0.016" diaginertia="3.37527e-06 2.863e-06 1.54873e-06"/>
                                <joint name="leap_hand_3" pos="0 0 0" axis="0 0 -1" range="-0.366 2.042" actuatorfrcrange="-0.95 0.95"/>
                                <geom pos="0.0132864 -0.00611424 0.0145" quat="0 1 0 0" type="mesh" rgba="0.866667 0.866667 0.0509804 1" mesh="fingertip"/>
                              </body>
                            </body>
                          </body>
                        </body>
                        <body name="mcp_joint_2" pos="-0.00709525 -0.0223922 -0.0187224" quat="0.5 0.5 0.5 -0.5">
                          <inertial pos="0 0 0" quat="0.388585 0.626468 -0.324549 0.592628" mass="0.044" diaginertia="1.47756e-05 1.31982e-05 6.0802e-06"/>
                          <joint name="leap_hand_5" pos="0 0 0" axis="0 0 -1" range="-0.314 2.23" actuatorfrcrange="-0.95 0.95"/>
                          <geom pos="0.0084069 0.00776624 0.0146574" quat="1 0 0 0" type="mesh" rgba="0.866667 0.866667 0.0509804 1" mesh="mcp_joint"/>
                          <body name="pip_2" pos="-0.0122 0.0381 0.0145" quat="0.5 -0.5 -0.5 0.5">
                            <inertial pos="0 0 0" quat="0.709913 0.704273 -0.000363156 0.00475427" mass="0.032" diaginertia="4.7981e-06 4.23406e-06 2.86184e-06"/>
                            <joint name="leap_hand_4" pos="0 0 0" axis="0 0 -1" range="-1.047 1.047" actuatorfrcrange="-0.95 0.95"/>
                            <geom pos="0.00964336 0.0003 0.000784034" quat="0.5 -0.5 -0.5 -0.5" type="mesh" rgba="0.74902 0.74902 0.74902 1" mesh="pip"/>
                            <body name="dip_2" pos="0.015 0.0143 -0.013" quat="0.5 0.5 -0.5 0.5">
                              <inertial pos="0 0 0" quat="-0.252689 0.659216 0.238844 0.666735" mass="0.037" diaginertia="6.68256e-06 6.24841e-06 5.02002e-06"/>
                              <joint name="leap_hand_6" pos="0 0 0" axis="0 0 -1" range="-0.506 1.885" actuatorfrcrange="-0.95 0.95"/>
                              <geom pos="0.0211334 -0.00843212 0.00978509" quat="0 -1 0 0" type="mesh" rgba="0.866667 0.866667 0.0509804 1" mesh="dip"/>
                              <body name="fingertip_2" pos="0 -0.0361 0.0002">
                                <inertial pos="0 0 0" quat="0.706755 0.706755 0.0223155 0.0223155" mass="0.016" diaginertia="3.37527e-06 2.863e-06 1.54873e-06"/>
                                <joint name="leap_hand_7" pos="0 0 0" axis="0 0 -1" range="-0.366 2.042" actuatorfrcrange="-0.95 0.95"/>
                                <geom pos="0.0132864 -0.00611424 0.0145" quat="0 1 0 0" type="mesh" rgba="0.866667 0.866667 0.0509804 1" mesh="fingertip"/>
                              </body>
                            </body>
                          </body>
                        </body>
                        <body name="mcp_joint_3" pos="-0.00709525 -0.0678422 -0.0187224" quat="0.5 0.5 0.5 -0.5">
                          <inertial pos="0 0 0" quat="0.388585 0.626468 -0.324549 0.592628" mass="0.044" diaginertia="1.47756e-05 1.31982e-05 6.0802e-06"/>
                          <joint name="leap_hand_9" pos="0 0 0" axis="0 0 -1" range="-0.314 2.23" actuatorfrcrange="-0.95 0.95"/>
                          <geom pos="0.0084069 0.00776624 0.0146574" quat="1 0 0 0" type="mesh" rgba="0.866667 0.866667 0.0509804 1" mesh="mcp_joint"/>
                          <body name="pip_3" pos="-0.0122 0.0381 0.0145" quat="0.5 -0.5 -0.5 0.5">
                            <inertial pos="0 0 0" quat="0.709913 0.704273 -0.000363156 0.00475427" mass="0.032" diaginertia="4.7981e-06 4.23406e-06 2.86184e-06"/>
                            <joint name="leap_hand_8" pos="0 0 0" axis="0 0 -1" range="-1.047 1.047" actuatorfrcrange="-0.95 0.95"/>
                            <geom pos="0.00964336 0.0003 0.000784034" quat="0.5 -0.5 -0.5 -0.5" type="mesh" rgba="0.74902 0.74902 0.74902 1" mesh="pip"/>
                            <body name="dip_3" pos="0.015 0.0143 -0.013" quat="0.5 0.5 -0.5 0.5">
                              <inertial pos="0 0 0" quat="-0.252689 0.659216 0.238844 0.666735" mass="0.037" diaginertia="6.68256e-06 6.24841e-06 5.02002e-06"/>
                              <joint name="leap_hand_10" pos="0 0 0" axis="0 0 -1" range="-0.506 1.885" actuatorfrcrange="-0.95 0.95"/>
                              <geom pos="0.0211334 -0.00843212 0.00978509" quat="0 -1 0 0" type="mesh" rgba="0.866667 0.866667 0.0509804 1" mesh="dip"/>
                              <body name="fingertip_3" pos="0 -0.0361 0.0002">
                                <inertial pos="0 0 0" quat="0.706755 0.706755 0.0223155 0.0223155" mass="0.016" diaginertia="3.37527e-06 2.863e-06 1.54873e-06"/>
                                <joint name="leap_hand_11" pos="0 0 0" axis="0 0 -1" range="-0.366 2.042" actuatorfrcrange="-0.95 0.95"/>
                                <geom pos="0.0132864 -0.00611424 0.0145" quat="0 1 0 0" type="mesh" rgba="0.866667 0.866667 0.0509804 1" mesh="fingertip"/>
                              </body>
                            </body>
                          </body>
                        </body>
                        <body name="pip_4" pos="-0.0693952 -0.00124224 -0.0216224" quat="0.707107 0 0.707107 0">
                          <inertial pos="0 0 0" quat="0.709913 0.704273 -0.000363156 0.00475427" mass="0.032" diaginertia="4.7981e-06 4.23406e-06 2.86184e-06"/>
                          <joint name="leap_hand_12" pos="0 0 0" axis="0 0 -1" range="-0.349 2.094" actuatorfrcrange="-0.95 0.95"/>
                          <geom pos="-0.00535664 0.0003 0.000784034" quat="0.5 -0.5 -0.5 -0.5" type="mesh" rgba="0.74902 0.74902 0.74902 1" mesh="pip"/>
                          <body name="thumb_pip" pos="0 0.0143 -0.013" quat="0.5 0.5 -0.5 0.5">
                            <inertial pos="0 0 0" mass="0.003" diaginertia="5.93e-07 5.49e-07 2.24e-07"/>
                            <joint name="leap_hand_13" pos="0 0 0" axis="0 0 -1" range="-0.47 2.443" actuatorfrcrange="-0.95 0.95"/>
                            <geom pos="0.0119619 0 -0.0158526" quat="0.707107 0.707107 0 0" type="mesh" rgba="0.866667 0.866667 0.0509804 1" mesh="thumb_pip"/>
                            <body name="thumb_dip" pos="0 0.0145 -0.017" quat="0.707107 -0.707107 0 0">
                              <inertial pos="0 0 0" quat="0.708624 0.704906 0.00637342 0.0303153" mass="0.038" diaginertia="8.48742e-06 7.67823e-06 3.82835e-06"/>
                              <joint name="leap_hand_14" pos="0 0 0" axis="0 0 -1" range="-1.2 1.9" actuatorfrcrange="-0.95 0.95"/>
                              <geom pos="0.0439687 0.057953 -0.00862868" quat="1 0 0 0" type="mesh" rgba="0.866667 0.866667 0.0509804 1" mesh="thumb_dip"/>
                              <body name="thumb_fingertip" pos="0 0.0466 0.0002" quat="0 0 0 1">
                                <inertial pos="0 0 0" quat="0.704307 0.709299 0.006848 -0.0282727" mass="0.049" diaginertia="2.03882e-05 1.98443e-05 4.32049e-06"/>
                                <joint name="leap_hand_15" pos="0 0 0" axis="0 0 -1" range="-1.34 1.88" actuatorfrcrange="-0.95 0.95"/>
                                <geom pos="0.0625595 0.0784597 0.0489929" quat="1 0 0 0" type="mesh" rgba="0.603922 0.14902 0.14902 1" mesh="thumb_fingertip"/>
                              </body>
                            </body>
                          </body>
                        </body>
                      </body>
                      <!-- LEAP HAND END -->








                    </body>
                  </body>
                </body>
              </body>
            </body>
          </body>
        </body>
      </body>
    </body>
  </worldbody>
  <actuator>

  <!-- joint_mobile_base_and_kinova_base -->
    <!-- <position name="joint_mobile_base_and_kinova_base" joint="joint_mobile_base_and_kinova_base" kp="0" kv="0" ctrlrange="-0 0" forcerange="-0 0"/> -->

    <position name="joint_1" joint="joint_1" kp="2000" kv="100" ctrlrange="-3.0615 3.0615" forcerange="-105 105"/>
    <position name="joint_2" joint="joint_2" kp="2000" kv="100" ctrlrange="-2.24 2.24" forcerange="-105 105"/>
    <position name="joint_3" joint="joint_3" kp="2000" kv="100" ctrlrange="0.0801 6.2031" forcerange="-105 105"/>
    <position name="joint_4" joint="joint_4" kp="2000" kv="100" ctrlrange="-2.57 2.57" forcerange="-105 105"/>
    <position name="joint_5" joint="joint_5" kp="500" kv="50" ctrlrange="-3.0615 3.0615" forcerange="-52 52"/>
    <position name="joint_6" joint="joint_6" kp="500" kv="50" ctrlrange="-2.09 2.09" forcerange="-52 52"/>
    <position name="joint_7" joint="joint_7" kp="500" kv="50" ctrlrange="-1.4915 4.6315" forcerange="-52 52"/>


    <!-- leap_hand joints 0 to 15 -->
    <position name="leap_hand_0" joint="leap_hand_0" kp="200" kv="10"/>
    <position name="leap_hand_1" joint="leap_hand_1" kp="200" kv="10"/>
    <position name="leap_hand_2" joint="leap_hand_2" kp="200" kv="10"/>
    <position name="leap_hand_3" joint="leap_hand_3" kp="200" kv="10"/>
    <position name="leap_hand_4" joint="leap_hand_4" kp="200" kv="10"/>
    <position name="leap_hand_5" joint="leap_hand_5" kp="200" kv="10"/>
    <position name="leap_hand_6" joint="leap_hand_6" kp="200" kv="10"/>
    <position name="leap_hand_7" joint="leap_hand_7" kp="200" kv="10"/>
    <position name="leap_hand_8" joint="leap_hand_8" kp="200" kv="10"/>
    <position name="leap_hand_9" joint="leap_hand_9" kp="200" kv="10"/>
    <position name="leap_hand_10" joint="leap_hand_10" kp="200" kv="10"/>
    <position name="leap_hand_11" joint="leap_hand_11" kp="200" kv="10"/>
    <position name="leap_hand_12" joint="leap_hand_12" kp="200" kv="10"/>
    <position name="leap_hand_13" joint="leap_hand_13" kp="200" kv="10"/>
    <position name="leap_hand_14" joint="leap_hand_14" kp="200" kv="10"/>
    <position name="leap_hand_15" joint="leap_hand_15" kp="200" kv="10"/>
    


  </actuator>
  <keyframe>
    <key name="home" qpos="0 0.26 3.14 -2.27 0 0.96 1.57 0 0 0 0 0 0 0 0 0 0 0 0 0 0 0 0"/>
    <key name="retract" qpos="0 -0.35 3.14 -2.54 0 -0.87 1.57 0 0 0 0 0 0 0 0 0 0 0 0 0 0 0 0"/>
  </keyframe>
</mujoco>
